Workbook
Name Refinery: 'Form Sa1'!$A$41:$K$48,'Form Sa1'!$A$61:$K$168
Name Z_808D63CE_AAC2_4BB4_99F0_D9F2ED9063AB_.wvu.PrintArea: 'Form Sa1'!$A$1:$K$1392

Sheet Read Me
A1: 1 | B1: Instruction Sheet | E1: General Information | H1: Form 1 | K1: Form E2 | N1: Form-Sa1
B2: Baseline Parameters | E2: Summary Sheet | H2: Emission Factor & GWP Backup | K2: Annex Addl Eqp List-Env | N2: Annex Project Activites List
B3: NF-1 BQ Bauxite Quality | E3: NF-2 Fuel Quality in CPP | H3: NF-3 PLF | K3: NF-4 Product Mix | N3: NF-5 Power Mix
B4: NF-6 Carbon Anode Production | E4: NF-7 Smelter CU | H4: NF-8 Others
A5: How to use this File
A6: 2 | B6: Please use the General Information sheet Sr No 7 and 8 to fill the data for the selection of No of years as a baseline Year (s). Year needs to be selected from the drop-down list w.r.t Baseline Years and Assessment year
A8: 3 | B8: Based on the selection years of baseline, the avarage data shall be calaculated automatically
A9: 4 | B9: Automatic calculation (to be found in the menu Formula/Calculation options) must be turned on. It is recommended that you go through the file from start to end. There are few functions which will guide you through the form which depend on previous input, such as cells changing colour if any input is not needed ( see colour codes below). However, sometimes it is relevant to first continue data input in another sheet before going on.
A12: 5 | B12: A cell is to be kept empty, if no data is required. The cell will not take 0 value.
A13: 6 | B13: In several fields you can choose from predefined inputs. For selecting from such a "drop-down list" either click with the mouse on the small arrow appearing at the right border of the cell, or press "Alt-CursorDown" when you have selected the cell. Some fields allow you to input your own text even if such a drop-down list exists. This is the case when drop-down lists contain empty list entries.
A16: 7 | B16: Error messages will occur sometimes when data entries are text of zero. However, the non-appearance of error messages is not a guarantee for correct calculations, as not always a data completeness test is possible. If no result appears in a green field, it can be assumed that some data is still missing. Special care must be taken of consistency of data with the units displayed.
A19: 8 | B19: Colour Codes and fonts:
E20: The formulae can be changed
E21: Please leave blank if no data is to be filled
E22: Fomulae Protected, Energy data summary
E23: Data not to be filled
E24: Fomulae protected, Emission data summary
B25: Yes | E25: Select from the list Yes or No
B26: Select | E26: Select from the list Yes or No or Not Applicable
E27: Please do not enter any data
E28: Emission calculation data inputs
B29: Lignite | E29: Selection from the list
A30: 9 | B30: Navigation panels on top of each sheet provide hyperlinks for quick jumps to individual input sectors. The first line ("Table of contents", "Previous sheet", "Next Sheet", "Summary") and the points "Top of Sheet" and "End of Sheet" are the same for all sheet. Depending on the sheet, further menu items are added. If the background colour of one of the hyperlink areas turned red, this indicates that data is missing in the related section (not in all sheet).
A33: 10 | B33: This template has been locked against any data entry except for yellow fields. However, for transparency reasons, no password has been set. This allows for complete viewing of all formulae. When using this file for data entry, it is recommended to keep the protection in force. The sheets should only be unprotected for checking the validity of formulae. It is recommended to do this in a separate file.
A36: 11 | B36: In order to protect formulae against unintended modifications, which usually lead to wrong and misleading results, it is of utmost importance NOT TO USE the CUT & PASTE feature. If you want to mode data, first COPY and PASTE them, and thereafter delete the unwanted data in the old (wrong) place.
A39: 12 | B39: Data fields have not been optimized for numerical and other formats. However, sheet protection has been limited so as to allow you to use your own formats. In particular, you may decide about the number of decimal places displayed. The number of places is in principle independent from the precision of calculation. In principle the option "Precision as displayed" of MS Excel should be deactivated. For more details, consult MS Excel's "Help" function on this topic.
A44: 11 | B44: DISCLAIMER: All formulae have been developed carefully and thoroughly. However, mistakes cannot be fully excluded. As described above, full transparency for checking the validity of calculations is ensured. Neither the authors of this file nor the Bureau of Energy Efficiency can be held liable for eventual damages resulting from wrong or misleading results of the provided calculations. It is the full responsibility of the user of this file (i.e., The Obligated Entity or Verifier to ensure that correct data is reported to the competent authority.

Sheet Instruction Sheet
A1: INSTRUCTION FOR FILLING UP THE FORM-Sa1 (Detail of production and Energy Consumption & CO2eq Emission) | H1: Go down
A2: Sr No | B2: Details | C2: Note | D2: Frequency of record | E2: Primary Documents from where the information can be sourced and to be kept ready for verification by Accredited Energy Auditor | F2: Secondary Documents from where the information can be sourced and to be kept ready for verification by Accredited Energy Auditor
A3: It is mandatory to fill data in all fields of the excel sheet - General Information, Form Sa1, Annex CPP, Annex Addl Eqp List-Env, Annex Project Activities List
A4: Please fill the data as per colour coding provided at the bottom of Form Sa1
A5: A | B5: Production and capacity utilization details
A6: A1 | B6: Refinery Process
A7: i | B7: Please provide total annual Production Capacity of Hydrate Alumina in tonnes | C7: Capacity of all Precipitar Tank | D7: Annual | E7: 1) OEM Document of Section-wise process line 2) Enviromental Consent to establish/operate document | F7: 1) Equipment/Section wise capacity document from OEM 2) Capacity calculation document submitted for Enviromental Consent
A8: ii | B8: Please provide total annual Production Capacity of Calcined Alumina in tonnes | C8: Capacity of Calciner | D8: Annual | E8: 1) OEM Document of Section-wise Process line 2) Enviromental Consent to establish/operate document | F8: 1) Equipment/Section wise capacity document from OEM 2) Capacity calculation document submitted for Enviromental Consent
A9: iii | B9: Please provide total annual Hydrate Alumina Production (including the exported hydrate alumina) in Tonnes | C9: Production of Hydrate Alumina from all Precipitor Tank | D9: Continuous, Hourly, Daily, Monthly | E9: 1) Log Sheet 2) CCR SCADA Report/ Trends 3) DPR 4) MPR 5) SAP Entry in PP/SD module 6) Excise record (ER1) 7) Annual Report | F9: 1)Hydrate Alumina stock Level 2) Weighhfeeders 3) Belt Weigher 4) Solid flow meter 5) Load cells
A10: iv | B10: Please provide total annual Calcined Alumina Production of all calciner (including the exported calcined alumina) in Tonnes | C10: Production of Calcined Alumina from all Calciner | D10: Continouous, Hourly, Daily, Monthly | E10: 1) Log Sheet 2) CCR SCADA Report/ Ternds 3) DPR 4) MPR 5) SAP Entry in PP/SD module 6) Excise record (ER1) 7) Annual Report | F10: 1)Calcined Alumina stock 2) Weighhfeeders 3) Belt Weigher 4) Solid flow meter 5) Load cells
A11: v | B11: Formula protected (Annual production of Hydrate Alumina/ Annual production capacity of Hydrate Alumina)
A12: vi | B12: Formula protected (Annual production of calcined Alummina/annual production capacity of Calcined Alumina)
A13: A2 | B13: Smelter Process
A14: i | B14: Please provide total annual Production Capacity of Molten Aluminium in tonnes | C14: Capacity of all Potline | D14: Annual | E14: 1) OEM Document of potline 2) Enviromental Consent to establish/operate document | F14: 1) Potline wise capacity document from OEM 2) Capacity calculation document submitted for Enviromental Consent
A15: ii | B15: Please provide total annual Production Capacity of cast House in tonnes | C15: Capacity of cast House | D15: Annual | E15: 1) OEM Document of Section-wise Process line 2) Enviromental Consent to establish/operate document | F15: 1) Equipment/Section wise capacity document from OEM 2) Capacity calculation document submitted for Enviromental Consent
A16: iii | B16: Please provide total annual Molten Aluminium Production in Tonnes | C16: Production of Molten Aluminium from all Potline | D16: Continuous, Hourly, Daily, Monthly | E16: 1) Log Sheet 2) CCR SCADA Report/ Ternds 3) DPR 4) MPR 5) SAP Entry in PP/SD module 6) Excise record (ER1) 7) Annual Report | F16: 1) Laddle weighing system 2) Weight of Molten Aluminium
A17: iv | B17: Please provide total annual cast house Production in Tonnes | C17: production of Casted product from Cast House | D17: Continuous, Hourly, Daily, Monthly | E17: 1) Log Sheet 2) CCR SCADA Report/ Ternds 3) DPR 4) MPR 5) SAP Entry in PP/SD module 6) Excise record (ER1) 7) Annual Report | F17: 1) Cast House Products stock register 2) Weigh Bridge
A18: v | B18: Formula protected (Annual production of Molten Aluminium/ Annual production capacity of Molten Aluminium)
A19: vi | B19: Formula protected (Annual production of Cast House/annual production capacity of Cast House)
A20: A3 | B20: Process wise production and performance detail
A21: A3.1 | B21: Refinery Process
A22: a | B22: Hydrate Alumina
A23: i | B23: Please provide the Hydrate Alumina, exported outside plant boundary or sold to any other entity in Tonnes. | D23: Monthly, Yearly | E23: 1) Inventory Report 2) Excise Document (ER1)3) Stores Entry 4) SAP Entry in MM/PP/SD module | F23: 1) Weigh Bridge 2) Stock Register
A24: ii | B24: Please provide the Hydrate Alumina, imported from outside plant boundary or import from any other entity in Tonnes. | D24: Monthly, Yearly | E24: 1) Inventory Report 2) Excise Document (ER1)3) Stores Entry 4) SAP Entry in MM/PP/SD module | F24: 1) Weigh Bridge 2) Stock Register
A25: iii | B25: Please provide opening stock of hydrate alumina in tonnes | C25: Record Opening and Closing stock on daily basis | D25: Daily, Monthly, Yearly | E25: 1) Inventory Report 2) Excise Document (ER1)3) Stores Entry 4) SAP Entry in MM/PP/SD module
A26: iv | B26: Please provide closing stock of hydrate alumina in tonnes | C26: Record Opening and Closing stock on daily basis | D26: Daily, Monthly, Yearly | E26: 1) Inventory Report 2) Excise Document (ER1)3) Stores Entry 4) SAP Entry in MM/PP/SD module
A27: v | B27: Please provide thermal SEC of hydrate alumina (total thermal energy consumed for production of hydrate alumina in kcal /total hydrate alumina production in tonne) | C27: The energy consumed upto making hydrate Alumina needs to be divided by total hydrate production | D27: Daily, Monthly, Yearly | E27: 1) DPR 2) MPR 3) Stocks register 4) Log Book 4) Annual Report 6) Fuel test Certificate (Internal and External) 7) Excise Record | F27: 1)Operator Shift Register 2) Weighfeeder Reading for fuel feeding 3) Weigher Reading
A28: vi | B28: Please provide electrical SEC of hydrate alumina (total electrical energy consumed for production of hydrate alumina in kWh/total hydrate alumina production in tonne) | D28: Daily, Monthly, Yearly | E28: 1) DPR 2) MPR 3) Stocks register 4) Log Book 4) Annual Report 6)Daily Power Report 7) Monthly Power Report 8) Excise Record | F28: 1)Operator Shift Register 2) Weighfeeder Reading for fuel feeding 3) Weigher Reading 4) Energy Meter Reading 5) Energy Management System
A29: vii | B29: Please provide total annual running Hours of plant for producing Hydrate Alumina | D29: Daily, Monthly, Yearly | E29: 1) DPR 2) MPR 3) DCS/CCR Trend | F29: 1) houer Meter Reading
A30: b | B30: Digestion Process Parameter
A31: i | B31: Please provide Type of Digestion Technology used in plant | E31: 1) OEM document | F31: 1) Name Plate Details
A32: ii | B32: Please provide Number of Digestion Units within the plant | E32: 1) CCR/DCS SCADA Screen Shots
A33: iii | B33: Please provide total annual Production Capacity of Digestion Units in tonne | E33: 1) OEM document | F33: 1) Name Plate Details
A34: iv | B34: Please provide Digestion Specific Steam Consumption (total steam consumed in tonne/total alumina production in tonne) | D34: Daily, Monthly, Yearly | E34: 1) DPR 2) MPR 3) CCR/DCS SCADA Trends 4) Log Book 5)Stock Register 6) Stores Receipt | F34: 1) Steam flow Meter 2) Shift Register
A35: v | B35: Please provide Digestion Specific Power Consumption (total power consumed kWh/total alumina production in tonne) | D35: Daily, Monthly, Yearly | E35: 1) DPR 2) MPR 3) CCR/DCS SCADA Trends 4) Log Book 5)Stock Register 6) Stores Receipt 7) Daily Power Report 8) Monthly Power Report | F35: 1) Energy Meter 2) Energy Management System
A36: vi | B36: Please provide Temperature of Low Temperature Digestion Units in oC | D36: Daily, Monthly, Yearly | E36: 1) SCADA Screen Shots 2) OEM Document 3) Log Book | F36: 1 ) RTDs 2) Temperature Meters
A37: vii | B37: Please provide Pressure of Low Temperature Digestion Units in kg/cm2 | D37: Daily, Monthly, Yearly | E37: 1) SCADA Screen Shots 2) OEM Document 3) Log Book | F37: 1 ) RTDs 2) Pressure Meters
A38: viii | B38: Please provide the temperature of High Temperature Digestion Units in oC | D38: Daily, Monthly, Yearly | E38: 1) SCADA Screen Shots 2) OEM Document 3) Log Book | F38: 1 ) RTDs 2) Temperature Meters
A39: ix | B39: Please provide pressure of High Temperature Digestion Units in kg/cm2 | D39: Daily, Monthly, Yearly | E39: 1) SCADA Screen Shots 2) OEM Document 3) Log Book | F39: 1 ) RTDs 2) Pressure Meters
A40: x | B40: Please provide LP Steam Temperature in oC | D40: Daily, Monthly, Yearly | E40: 1) SCADA Screen Shots 2) OEM Document 3) Log Book | F40: 1 ) RTDs 2) Temperature Meters
...

Sheet General Information
A1: Form-Sa1 (General Information)
A2: Sector - Aluminium Sector
A3: 1 | B3: Name of the Unit | C3: HINDALCO INDUSTRIES LIMITED
A4: 2 | B4: Sub Sector | C4: INTEGRATED | E4: Subsector | G4: =C4 -> INTEGRATED
A5: 3 | B5: Major Product | C5: MOLTEN ALUMINIUM
A6: 4 | B6: i) Year of Establishment | C6: 1962
B7: ii) Registration No (As provided by BEE) | C7: ALM0009UP
A8: 5 | B8: Plant Contact Details & Address
A9: a | B9: City/Town/Village | C9: RENUKOOT
B10: District | C10: SONBHADRA
B11: State | C11: UTTAR PRADESH | E11: Pin | F11: 231217
B12: Telephone | C12: (05446) 252077-79 / 254791-96 | E12: Fax | F12: (05446) 252107 / 252427
A13: b | B13: Plant's Chief Executive Name | C13: Sameer Nayak
B14: Designation | C14: CHIEF OFFICER-OPERATIONS
B15: Telephone | C15: (05446) 252077-79 / 254791-96 | E15: Fax | F15: (05446) 252107 / 252427
B16: Mobile | C16: 8146628220 | D16: E-mail | E16: sameer.nayak@adityabirla.com
A17: 6 | B17: Registered Office
B18: Company's Chief Executive Name | C18: Satish Pai
B19: Designation | C19: M.D
B20: Address | C20: Ahura Center, Ist Floor, B Wing, Mahakali Caves Road, Andheri (East)
B21: City/Town/Village | C21: 91–22– 2422 7586/2436 2516 | E21: P.O.
B22: District | C22: MUMBAI
B23: State | C23: MAHARASTRA | E23: Pin | F23: 400030
B24: Telephone | C24: 91-22-6662 6666 | E24: Fax | F24: 91–22– 2422 7586/2436 2516
A25: 7 | B25: Energy Manager Details
B26: Name | C26: Vivek Agrawal
B27: Designation | C27: Asst. General Manager | E27: Whether EA or EM | G27: EA
B28: EA/EM Registration No. | C28: 27303
B29: Telephone | C29: (05446) 252077-79 / 254791-96 | E29: Fax | F29: (05446) 252107 / 252427
B30: Mobile | C30: 8114005777 | D30: E-mail ID | E30: (05446) 252107 / 252427
B31: Baseline/ Previous Year (FY ) | C31: FY: 2021-22 | D31: Current/Asssesment/Target Year | G31: FY: 2022-23
A32: 8 | B32: Current / Assessment / Target Period Details
B33: ="Current / Assessment / Target Year Corresponds to" -> Current / Assessment / Target Year Corresponds to | C33: 2025-26
A34: 9 | B34: Base Period Details
A35: A | B35: Number of years' data the unit is required to report as 'Base Period Data' | C35: 1
A36: B | B36: =IF(C35=1,"Base Year Corresponds to","First Base Period Year Corresponds to") -> Base Year Corresponds to | C36: 2023-24
B37: =IF(C35=1," ","Second Base Period Year Corresponds to") | C37: 2022-23
B38: =IF(C35=3,"Third Base Period Year Corresponds to"," ") | C38: 2021-22
A40: 10 | B40: Amendment
A41: S.No | B41: Version No | C41: Date | D41: Details
...

Sheet Form 1
A1: Form-1
A2: Details of information regarding Total Energy Consumed and Specific Energy Consumption Per unit of Production
A3: (See Rule 3)
A4: A. | B4: General Details | C4: Description
A5: 1 | B5: Name of the Unit | C5: ='General Information'!C3 -> HINDALCO INDUSTRIES LIMITED
A6: 2. (i) | B6: Year of Establishment | C6: ='General Information'!C6 -> 1962
A7: 2. (ii) | B7: Registration No (As provided by BEE) | C7: ='General Information'!C7 -> ALM0009UP
A8: 3 | B8: Sector and Sub-Sector in which the Designated Consumer falls | C8: Sector | E8: Sub-Sector
C9: ='General Information'!A2 -> Sector - Aluminium Sector | E9: ='General Information'!G4 -> INTEGRATED
A10: 4. (i) | B10: Complete address of DCs Unit location (including Chief Executive's name & designation) with mobile, telephone, fax nos. & e-mail. | C10: ='General Information'!C9&", "&'General Information'!C10&", "&'General Information'!C11&", "&'General Information'!F11&", "&'General Information'!C12&", "&'General Information'!F12&","&'General Information'!C13&", "&'General Information'!C14&", "&'General Information'!C15&", "&'General Information'!C16&", "&'General Information'!F15&", "&'General Information'!F16 -> RENUKOOT, SONBHADRA, UTTAR PRADESH, 231217, (05446) 252077-79 / 254791-96, (05446) 252107 / 252427,Sameer Nayak, CHIEF OFFICER-OPERATIONS , (05446) 252077-79 / 254791-96, 8146628220, (05446) 252107 / 252427,
A11: (ii) | B11: Registered Office address with telephone, fax nos. & e-mail | C11: ='General Information'!C18&", "&'General Information'!C19&", "&'General Information'!C20&","&'General Information'!C21&","&'General Information'!F21&","&'General Information'!C22&", "&'General Information'!C23&", "&'General Information'!F23&", "&'General Information'!C24&", "&'General Information'!F24 -> Satish Pai, M.D, Ahura Center, Ist Floor, B Wing, Mahakali Caves Road, Andheri (East),91–22– 2422 7586/2436 2516,,MUMBAI, MAHARASTRA, 400030, 91-22-6662 6666, 91–22– 2422 7586/2436 2516
A12: (iii) | B12: Energy Manager's Name, designation, Registration No., Address, Mobile, Telephone, Fax nos. & e-mail | C12: ='General Information'!C26&", "&'General Information'!C27&", "&'General Information'!G27&","&'General Information'!C28&","&'General Information'!C29&", "&'General Information'!F29&", "&'General Information'!C30&", "&'General Information'!E30 -> Vivek Agrawal, Asst. General Manager, EA,27303,(05446) 252077-79 / 254791-96, (05446) 252107 / 252427, 8114005777, (05446) 252107 / 252427
A13: B. | B13: Production details
A14: 5 | B14: Manufacturing Industries notified as Designated Consumers
A15: Sr No | B15: Products | C15: Unit | D15: Baseline/Previous Year | E15: Assesment year/ Current Year
D16: ="FY "&'Form Sa1'!H9 -> FY 2023-24 | E16: ="FY "&'Form Sa1'!I9 -> FY 2025-26
A17: (i) | B17: =IF(OR('General Information'!C4="SMELTER", 'General Information'!C4="INTEGRATED"),'Form Sa1'!B54, 'Form Sa1'!B45) -> Total Molten Aluminium Production | C17: Tonne | D17: =IF(OR('General Information'!$C$4="SMELTER", 'General Information'!$C$4="INTEGRATED"), 'Form Sa1'!H54, 'Form Sa1'!H45) -> 410661.74 | E17: =IF(OR('General Information'!$C$4="SMELTER", 'General Information'!$C$4="INTEGRATED"), 'Form Sa1'!I54, 'Form Sa1'!I45) -> 0
A18: (ii) | B18: =IF(OR('General Information'!$C$4="SMELTER", 'General Information'!$C$4="INTEGRATED"), 'Form Sa1'!B55, 'Form Sa1'!B46) -> Total Production- Cast House | C18: Tonne | D18: =IF(OR('General Information'!$C$4="SMELTER", 'General Information'!$C$4="INTEGRATED"), 'Form Sa1'!H55, 'Form Sa1'!H46) -> 381860.33 | E18: =IF(OR('General Information'!$C$4="SMELTER", 'General Information'!$C$4="INTEGRATED"), 'Form Sa1'!I55, 'Form Sa1'!I46) -> 0
A19: (iii) | B19: =IF(OR('General Information'!$C$4="SMELTER", 'General Information'!$C$4="INTEGRATED"), 'Form Sa1'!B384, 'Form Sa1'!B110) -> Actual Carbon Anode Production | C19: Tonne | D19: =IF(OR('General Information'!$C$4="SMELTER", 'General Information'!$C$4="INTEGRATED"), 'Form Sa1'!H384, 'Form Sa1'!H112) -> 219298.18 | E19: =IF(OR('General Information'!$C$4="SMELTER", 'General Information'!$C$4="INTEGRATED"), 'Form Sa1'!I384, 'Form Sa1'!I112) -> 0
A20: (iv) | B20: =IF(OR('General Information'!$C$4="SMELTER", 'General Information'!$C$4="INTEGRATED"), 'Form Sa1'!B394, 'Form Sa1'!B116) -> Billets | C20: Tonne | D20: =IF(OR('General Information'!$C$4="SMELTER", 'General Information'!$C$4="INTEGRATED"), 'Form Sa1'!H396, 'Form Sa1'!H118) -> 58980.666 | E20: =IF(OR('General Information'!$C$4="SMELTER", 'General Information'!$C$4="INTEGRATED"), 'Form Sa1'!I396, 'Form Sa1'!I118) -> 0
A21: (v) | B21: =IF(OR('General Information'!$C$4="SMELTER", 'General Information'!$C$4="INTEGRATED"), 'Form Sa1'!B400, 'Form Sa1'!B122) -> Ingot | C21: Tonne | D21: =IF(OR('General Information'!$C$4="SMELTER", 'General Information'!$C$4="INTEGRATED"), 'Form Sa1'!H402, 'Form Sa1'!H124) -> 210775.16 | E21: =IF(OR('General Information'!$C$4="SMELTER", 'General Information'!$C$4="INTEGRATED"), 'Form Sa1'!I402, 'Form Sa1'!I124) -> 0
A22: (vi) | B22: =IF(OR('General Information'!$C$4="SMELTER", 'General Information'!$C$4="INTEGRATED"), 'Form Sa1'!B406, 'Form Sa1'!B128) -> Bars | C22: Tonne | D22: =IF(OR('General Information'!$C$4="SMELTER", 'General Information'!$C$4="INTEGRATED"), 'Form Sa1'!H408, 'Form Sa1'!H130) -> 0 | E22: =IF(OR('General Information'!$C$4="SMELTER", 'General Information'!$C$4="INTEGRATED"), 'Form Sa1'!I408, 'Form Sa1'!I130) -> 0
A23: (vii) | B23: =IF(OR('General Information'!$C$4="SMELTER", 'General Information'!$C$4="INTEGRATED"), 'Form Sa1'!B412, 'Form Sa1'!B134) -> Primary Foundry Alloys | C23: Tonne | D23: =IF(OR('General Information'!$C$4="SMELTER", 'General Information'!$C$4="INTEGRATED"), 'Form Sa1'!H414, 'Form Sa1'!H136) -> 0 | E23: =IF(OR('General Information'!$C$4="SMELTER", 'General Information'!$C$4="INTEGRATED"), 'Form Sa1'!I414, 'Form Sa1'!I136) -> 0
A24: (viii) | B24: =IF(OR('General Information'!$C$4="SMELTER", 'General Information'!$C$4="INTEGRATED"), 'Form Sa1'!B418, 'Form Sa1'!B140) -> Wire Rod | C24: Tonne | D24: =IF(OR('General Information'!$C$4="SMELTER", 'General Information'!$C$4="INTEGRATED"), 'Form Sa1'!H420, 'Form Sa1'!H142) -> 55481.148 | E24: =IF(OR('General Information'!$C$4="SMELTER", 'General Information'!$C$4="INTEGRATED"), 'Form Sa1'!I420, 'Form Sa1'!I142) -> 0
A25: (ix) | B25: =IF(OR('General Information'!$C$4="SMELTER", 'General Information'!$C$4="INTEGRATED"), 'Form Sa1'!B424, 'Form Sa1'!B146) -> Strips | C25: Tonne | D25: =IF(OR('General Information'!$C$4="SMELTER", 'General Information'!$C$4="INTEGRATED"), 'Form Sa1'!H426, 'Form Sa1'!H148) -> 76567.049 | E25: =IF(OR('General Information'!$C$4="SMELTER", 'General Information'!$C$4="INTEGRATED"), 'Form Sa1'!I426, 'Form Sa1'!I148) -> 0
A26: (x) | B26: =IF(OR('General Information'!$C$4="SMELTER", 'General Information'!$C$4="INTEGRATED"), 'Form Sa1'!B430, 'Form Sa1'!B152) -> Others , if Any | C26: Tonne | D26: =IF(OR('General Information'!$C$4="SMELTER", 'General Information'!$C$4="INTEGRATED"), 'Form Sa1'!H433, 'Form Sa1'!H154) -> 42078.393 | E26: =IF(OR('General Information'!$C$4="SMELTER", 'General Information'!$C$4="INTEGRATED"), 'Form Sa1'!I433, 'Form Sa1'!I154) -> 0
A27: (xi) | B27: =IF(OR('General Information'!$C$4="SMELTER", 'General Information'!$C$4="INTEGRATED"), "-",'Form Sa1'!B158) -> - | C27: Tonne | D27: =IF(OR('General Information'!$C$4="SMELTER", 'General Information'!$C$4="INTEGRATED"), "-", 'Form Sa1'!H160) -> - | E27: =IF(OR('General Information'!$C$4="SMELTER", 'General Information'!$C$4="INTEGRATED"), "-", 'Form Sa1'!I160) -> -
A28: (xii) | B28: =IF(OR('General Information'!$C$4="SMELTER", 'General Information'!$C$4="INTEGRATED"), "-", 'Form Sa1'!B164) -> - | C28: Tonne | D28: =IF(OR('General Information'!$C$4="SMELTER", 'General Information'!$C$4="INTEGRATED"), "-", 'Form Sa1'!H167) -> - | E28: =IF(OR('General Information'!$C$4="SMELTER", 'General Information'!$C$4="INTEGRATED"), "-", 'Form Sa1'!I167) -> -
A29: (xiii) | B29: Product (Please add extra rows in case of additional products) | C29: Tonne
A30: (xiv) | B30: =IF(OR('General Information'!$C$4="SMELTER", 'General Information'!$C$4="INTEGRATED"), 'Baseline Parameter'!B73,'Baseline Parameter'!B70) -> Total Equivalent Molten Aluminum Produced | C30: Tonne | D30: =' Summary Sheet'!E102 -> 423703.51 | E30: =' Summary Sheet'!F102 -> 0
A31: C | B31: Energy Consumption Details of Manufacturing Industries notified as Designated Consumers
A32: Sr No | B32: Item | C32: Unit | D32: Previous Year | E32: Current Year
C33: (1) | D33: (2) | E33: (3)
A34: 6. (i) | B34: Total Electricity Purchased from Grid/Other Source | C34: Million kwh | D34: =('Form Sa1'!H716/10)+('Form Sa1'!H814/10) -> 118.39134 | E34: =('Form Sa1'!I716/10)+('Form Sa1'!I814/10) -> 0
A35: (ii) | B35: Total Electricity Generated | C35: Million kwh | D35: ='Form Sa1'!H839/10 -> 7087.2925 | E35: ='Form Sa1'!I839/10 -> 0
A36: (iii) | B36: Total Electricity Exported | C36: Million kwh | D36: =('Form Sa1'!H841+'Form Sa1'!H842)/10 -> 178.26538 | E36: =('Form Sa1'!I841+'Form Sa1'!I842)/10 -> 0
A37: (iv) | B37: Total Electrical Energy Consumption | C37: Million kwh | D37: ='Form Sa1'!H845/10 -> 7027.4185 | E37: ='Form Sa1'!I845/10 -> 0
A38: (v) | B38: Total Solid Fuel Consumption | C38: Million kCal | D38: ='Form Sa1'!H1012+'Form Sa1'!H1013+'Form Sa1'!H1014 -> 19863268 | E38: ='Form Sa1'!I1012+'Form Sa1'!I1013+'Form Sa1'!I1014 -> 0
A39: (vi) | B39: Total Liquid Fuel Consumption | C39: Million kCal | D39: ='Form Sa1'!H1171+'Form Sa1'!H1172+'Form Sa1'!H1173+'Form Sa1'!H1174 -> 716331.99 | E39: ='Form Sa1'!I1171+'Form Sa1'!I1172+'Form Sa1'!I1173+'Form Sa1'!I1174 -> 0
A40: (vii) | B40: Total Gaseous Fuel Consumption | C40: Million kCal | D40: ='Form Sa1'!H1217+'Form Sa1'!H1218+'Form Sa1'!H1265 -> 5167.7007 | E40: ='Form Sa1'!I1217+'Form Sa1'!I1218+'Form Sa1'!I1265 -> 0
...

Sheet Form PE
A1: S. No | B1: Particulars | C1: Basis/ Calculation | D1: Unit | E1: Year1 (20.... 20...) | F1: Year2 (20.... 20...) | G1: ="Baseline/ Previous Year (FY ) " & 'Form 1'!D11 -> Baseline/ Previous Year (FY ) | H1: =G1 -> Baseline/ Previous Year (FY ) | I1: ="Current/Asssesment/Target Year "&'Form 1'!E11 -> Current/Asssesment/Target Year | J1: Source of Data
A2: A | B2: Tier 1 - calculation for CO2 emisisons from anode consumption
A3: (i) | B3: Molten Aluminium Production | C3: Annual | D3: t | E3: 1 | F3: 1 | G3: 1 | H3: 1 | I3: 1
A4: (ii) | B4: Select Technology | C4: Value | D4: - | E4: Prebake | F4: Prebake | G4: Prebake | H4: Prebake | I4: Prebake
A5: (iii) | B5: Emission Factor for CO2 from process emissions | C5: Default | D5: t CO2/t al | E5: =IF(E4="Soderberg",E56,E55) -> 1.6 | F5: =IF(F4="Soderberg",F56,F55) -> 1.6 | G5: =IF(G4="Soderberg",G56,G55) -> 1.6 | H5: =IF(H4="Soderberg",H56,H55) -> 1.6 | I5: =IF(I4="Soderberg",I56,I55) -> 1.6
A6: (iv) | B6: Process CO2 emissions from Aluminium Production | C6: D (i) x D (iii) | D6: t CO2 | E6: =E5*E3 -> 1.6 | F6: =F5*F3 -> 1.6 | G6: =G5*G3 -> 1.6 | H6: =H5*H3 -> 1.6 | I6: =I5*I3 -> 1.6 | O6: Soderberg
A7: B | B7: Tier 1 - calculation for CO2 emisisons from anode consumption | O7: Prebake
A8: (i) | B8: Select Technology | C8: Value | D8: - | E8: HSS | F8: HSS | G8: CWPB | H8: HSS | I8: HSS
A9: (ii) | B9: Emission Factor for CF4 from process emissions | C9: Default | D9: kg CF4/t al | E9: =IF(E8=$B$58,E58,IF(E8=$B$59,E59,IF(E8=$B$60,E60,IF(E8=$B$61,E61,0)))) -> 0.4 | F9: =IF(F8=$B$58,F58,IF(F8=$B$59,F59,IF(F8=$B$60,F60,IF(F8=$B$61,F61,0)))) -> 0.4 | G9: =IF(G8=$B$58,G58,IF(G8=$B$59,G59,IF(G8=$B$60,G60,IF(G8=$B$61,G61,0)))) -> 0.4 | H9: =IF(H8=$B$58,H58,IF(H8=$B$59,H59,IF(H8=$B$60,H60,IF(H8=$B$61,H61,0)))) -> 0.4 | I9: =IF(I8=$B$58,I58,IF(I8=$B$59,I59,IF(I8=$B$60,I60,IF(I8=$B$61,I61,0)))) -> 0.4 | O9: CWPB
A10: (iii) | B10: Emission Factor for C2F6 from process emissions | C10: Default | D10: kg C2F6/t al | E10: =IF(E8=B63,E63,IF(E8=B64,E64,IF(E8=B65,E65,IF(E8=B66,E66,0)))) -> 0.03 | F10: =IF(F8=C63,F63,IF(F8=C64,F64,IF(F8=C65,F65,IF(F8=C66,F66,0)))) -> 0 | G10: =IF(G8=D63,G63,IF(G8=D64,G64,IF(G8=D65,G65,IF(G8=D66,G66,0)))) -> 0 | H10: =IF(H8=E63,H63,IF(H8=E64,H64,IF(H8=E65,H65,IF(H8=E66,H66,0)))) -> 0 | I10: =IF(I8=F63,I63,IF(I8=F64,I64,IF(I8=F65,I65,IF(I8=F66,I66,0)))) -> 0 | O10: SWPB
A11: (iv) | B11: GWP for CF4 as per BUR 3 | C11: Default | D11: kg CO2/kg CF4 | E11: 6500 | F11: 6500 | G11: 6500 | H11: 6500 | I11: 6500
A12: (v) | B12: GWP for C2F6 as per BUR 3 | C12: Default | D12: kg CO2/kg C2F6 | E12: 9200 | F12: 9200 | G12: 9200 | H12: 9200 | I12: 9200
A13: (vi) | B13: Total CO2 eq emission from anode consumption | C13: (D (i)* E (ii)* E (iv) +D(i) * E(iii) * E(v))/1000 | D13: t CO2 eq | E13: =(E3*E9*E11+E3*E10*E12)/1000 -> 2.876 | F13: =(F3*F9*F11+F3*F10*F12)/1000 -> 2.6 | G13: =(G3*G9*G11+G3*G10*G12)/1000 -> 2.6 | H13: =(H3*H9*H11+H3*H10*H12)/1000 -> 2.6 | I13: =(I3*I9*I11+I3*I10*I12)/1000 -> 2.6
A14: C | B14: TIER 2/3 method for calculating CO2 emissions from prebake anode consumption
A15: (i) | B15: Molten Aluminium Production | C15: Annual | D15: t al
A16: (ii) | B16: Net Anode Consumption | C16: Annual | D16: t/ t Al
A17: (iii) | B17: Sulphur content in baked anodes (default value = 2) | C17: Average | D17: % wt
A18: (iv) | B18: Ash content in baked anodes (default value - 0.4%) | C18: Average | D18: % wt
A19: (v) | B19: Total CO2 emissions from from Anode Consumption | C19: Annual | D19: t CO2 | E19: =(E15*E16*((100-E17-E18)/100))*44/12 -> 0 | F19: =(F15*F16*((100-F17-F18)/100))*44/12 -> 0 | G19: =(G15*G16*((100-G17-G18)/100))*44/12 -> 0 | H19: =(H15*H16*((100-H17-H18)/100))*44/12 -> 0 | I19: =(I15*I16*((100-I17-I18)/100))*44/12 -> 0
A20: D | B20: Tier 2/3 Method for calculating Pitch Volatlie oxidation from pitch volatile combustion
A21: (i) | B21: Weight of Green Anode | C21: Average | D21: t
A22: (ii) | B22: Weight of Baked Anode | C22: Average | D22: t
A23: (iii) | B23: Baked Anode Production | C23: Annual | D23: t
A24: (iv) | B24: Weight of loaded green anodes | C24: Annual | D24: t | E24: =(E21/E22)*E23 -> #DIV/0! | F24: =(F21/F22)*F23 -> #DIV/0! | G24: =(G21/G22)*G23 -> #DIV/0! | H24: =(H21/H22)*H23 -> #DIV/0! | I24: =(I21/I22)*I23 -> #DIV/0!
A25: (v) | B25: Hydrogen content in green anodes (default value 0.5) | C25: Average | D25: %
A26: (vi) | B26: Waste tar collected (Default for riedhammer furnace 0.005 x GA and 0 for others) | C26: Annual | D26: t
A27: (vii) | B27: Annual CO2 emissions from pitch volatie oxidation | C27: Annual | D27: t CO2 | E27: =((E24-((E25*E24)/100)-E23-E26)*44/12) -> #DIV/0! | F27: =((F24-((F25*F24)/100)-F23-F26)*44/12) -> #DIV/0! | G27: =((G24-((G25*G24)/100)-G23-G26)*44/12) -> #DIV/0! | H27: =((H24-((H25*H24)/100)-H23-H26)*44/12) -> #DIV/0! | I27: =((I24-((I25*I24)/100)-I23-I26)*44/12) -> #DIV/0!
A28: E | B28: Tier 2/3 Method for carbon emissions from Packing Coke
A29: (i) | B29: Packing Coke consumed tonnes per tonne of baked anode (Default value 0.015) | C29: Average | D29: t/t | E29: 0.015 | F29: 0.015 | G29: 0.015 | H29: 0.015 | I29: 0.015
A30: (ii) | B30: Baked Anode Production | C30: Annual | D30: t | E30: 1 | F30: 1 | G30: 1 | H30: 1 | I30: 1
A31: (iii) | B31: Sulphur content in packing coke (default value 2) | C31: Average | D31: % | E31: 2 | F31: 2 | G31: 2 | H31: 2 | I31: 2
A32: (iv) | B32: Ash content in packing coke (Default value 2.5) | C32: Average | D32: % | E32: 2.5 | F32: 2.5 | G32: 2.5 | H32: 2.5 | I32: 2.5
A33: (v) | B33: Annual CO2 emission from packing coke | C33: Annual | D33: t CO2 | E33: =(E29*E30*(100-E31-E32)/100)*44/12 -> 0.052525 | F33: =(F29*F30*(100-F31-F32)/100)*44/12 -> 0.052525 | G33: =(G29*G30*(100-G31-G32)/100)*44/12 -> 0.052525 | H33: =(H29*H30*(100-H31-H32)/100)*44/12 -> 0.052525 | I33: =(I29*I30*(100-I31-I32)/100)*44/12 -> 0.052525
A34: F | B34: Tier 2 Method for CF4 and C2F6 per tonne aluminum using Anode Effect Minutes per cell day (Slope Method)
A35: (i) | B35: Select Technology | C35: - | D35: - | E35: SWPB | F35: SWPB | G35: SWPB | H35: SWPB | I35: SWPB
A36: (ii) | B36: Slope Coefficient | C36: Default | D36: (kg CF4/t al)/ (AE-Mins/cell-day) | E36: =IF(E35=$B$68,E68,IF(E35=$B$69,E69,IF(E35=$B$70,E70,IF(E35=$B$71,E71)*0))) -> 0.272 | F36: =IF(F35=$B$68,F68,IF(F35=$B$69,F69,IF(F35=$B$70,F70,IF(F35=$B$71,F71)*0))) -> 0.272 | G36: =IF(G35=$B$68,G68,IF(G35=$B$69,G69,IF(G35=$B$70,G70,IF(G35=$B$71,G71)*0))) -> 0.272 | H36: =IF(H35=$B$68,H68,IF(H35=$B$69,H69,IF(H35=$B$70,H70,IF(H35=$B$71,H71)*0))) -> 0.272 | I36: =IF(I35=$B$68,I68,IF(I35=$B$69,I69,IF(I35=$B$70,I70,IF(I35=$B$71,I71)*0))) -> 0.272
A37: (iii) | B37: Weight Fraction C2F6/CF4 | C37: Default | D37: Weigh Fraction C2F6/CF4 | E37: =IF(E35=$B$78,E78,IF(E35=$B$79,E79,IF(E35=$B$80,E80,IF(E35=$B$81,E81,0)))) -> 0.252 | F37: =IF(F35=$B$78,F78,IF(F35=$B$79,F79,IF(F35=$B$80,F80,IF(F35=$B$81,F81,0)))) -> 0.252 | G37: =IF(G35=$B$78,G78,IF(G35=$B$79,G79,IF(G35=$B$80,G80,IF(G35=$B$81,G81,0)))) -> 0.252 | H37: =IF(H35=$B$78,H78,IF(H35=$B$79,H79,IF(H35=$B$80,H80,IF(H35=$B$81,H81,0)))) -> 0.252 | I37: =IF(I35=$B$78,I78,IF(I35=$B$79,I79,IF(I35=$B$80,I80,IF(I35=$B$81,I81,0)))) -> 0.252
A38: (iv) | B38: Anode Effect mintues per cell day | C38: Average | D38: AE-m/cell-day
A39: (v) | B39: Emission rate for CF4 | C39: Average | D39: kg CF4/t al | E39: =E38*E36 -> 0 | F39: =F38*F36 -> 0 | G39: =G38*G36 -> 0 | H39: =H38*H36 -> 0 | I39: =I38*I36 -> 0
A40: (vi) | B40: Emission rate for C2F6 | C40: Average | D40: kg C2F6/t al | E40: =E39*E37 -> 0 | F40: =F39*F37 -> 0 | G40: =G39*G37 -> 0 | H40: =H39*H37 -> 0 | I40: =I39*I37 -> 0
...

Sheet Form E2
A1: Form-E2
A2: Energy and Emission Form
A3: Section-A: General Details
A4: Sr No | B4: Details | C4: Description
A5: A1 | B5: Registration No | C5: ='General Information'!C7 -> ALM0009UP
A6: A2 | B6: Obligated Entity Name | C6: ='General Information'!C3 -> HINDALCO INDUSTRIES LIMITED
A7: A3 | B7: Sector and Sub-Sector in which the Designated Consumer falls | C7: Sector | E7: Sub-Sector
C8: ='General Information'!A2 -> Sector - Aluminium Sector | E8: ='General Information'!G4 -> INTEGRATED
A9: A4 | B9: Year of Establishment | C9: ='General Information'!C6 -> 1962
A10: A5 | B10: Complete address of DCs Unit location (including Chief Executive's name & designation) with mobile, telephone, fax nos. & e-mail. | C10: ='General Information'!C9&", "&'General Information'!C10&", "&'General Information'!C11&", "&'General Information'!F11&", "&'General Information'!C12&", "&'General Information'!F12&","&'General Information'!C13&", "&'General Information'!C14&", "&'General Information'!C15&", "&'General Information'!C16&", "&'General Information'!F15&", "&'General Information'!F16 -> RENUKOOT, SONBHADRA, UTTAR PRADESH, 231217, (05446) 252077-79 / 254791-96, (05446) 252107 / 252427,Sameer Nayak, CHIEF OFFICER-OPERATIONS , (05446) 252077-79 / 254791-96, 8146628220, (05446) 252107 / 252427,
A11: A6 | B11: Registered Office address with telephone, fax nos. & e-mail | C11: ='General Information'!C18&", "&'General Information'!C19&", "&'General Information'!C20&","&'General Information'!C21&","&'General Information'!F21&","&'General Information'!C22&", "&'General Information'!C23&", "&'General Information'!F23&", "&'General Information'!C24&", "&'General Information'!F24 -> Satish Pai, M.D, Ahura Center, Ist Floor, B Wing, Mahakali Caves Road, Andheri (East),91–22– 2422 7586/2436 2516,,MUMBAI, MAHARASTRA, 400030, 91-22-6662 6666, 91–22– 2422 7586/2436 2516
A12: A7 | B12: Energy Manager's Name, designation, Registration No., Address, Mobile, Telephone, Fax nos. & e-mail | C12: ='General Information'!C26&", "&'General Information'!C27&", "&'General Information'!G27&","&'General Information'!C28&","&'General Information'!C29&", "&'General Information'!F29&", "&'General Information'!C30&", "&'General Information'!E30 -> Vivek Agrawal, Asst. General Manager, EA,27303,(05446) 252077-79 / 254791-96, (05446) 252107 / 252427, 8114005777, (05446) 252107 / 252427
A13: B. Production, Energy Consumption and Emission Details
A14: B1 | B14: Production Details
A15: Sr No | B15: Products | C15: Unit | D15: Baseline/Previous Year | E15: Assesment year/ Current Year
D16: ='Form 1'!D16 -> FY 2023-24 | E16: ='Form 1'!E16 -> FY 2025-26
A17: (i) | B17: =IF(OR('General Information'!C4="SMELTER", 'General Information'!C4="INTEGRATED"),'Form Sa1'!B54, 'Form Sa1'!B45) -> Total Molten Aluminium Production | C17: Tonne | D17: =IF(OR('General Information'!$C$4="SMELTER", 'General Information'!$C$4="INTEGRATED"), 'Form Sa1'!H54, 'Form Sa1'!H45) -> 410661.74 | E17: =IF(OR('General Information'!$C$4="SMELTER", 'General Information'!$C$4="INTEGRATED"), 'Form Sa1'!I54, 'Form Sa1'!I45) -> 0
A18: (ii) | B18: =IF(OR('General Information'!$C$4="SMELTER", 'General Information'!$C$4="INTEGRATED"), 'Form Sa1'!B55, 'Form Sa1'!B46) -> Total Production- Cast House | C18: Tonne | D18: =IF(OR('General Information'!$C$4="SMELTER", 'General Information'!$C$4="INTEGRATED"), 'Form Sa1'!H55, 'Form Sa1'!H46) -> 381860.33 | E18: =IF(OR('General Information'!$C$4="SMELTER", 'General Information'!$C$4="INTEGRATED"), 'Form Sa1'!I55, 'Form Sa1'!I46) -> 0
A19: (iii) | B19: =IF(OR('General Information'!$C$4="SMELTER", 'General Information'!$C$4="INTEGRATED"), 'Form Sa1'!B384, 'Form Sa1'!B110) -> Actual Carbon Anode Production | C19: Tonne | D19: =IF(OR('General Information'!$C$4="SMELTER", 'General Information'!$C$4="INTEGRATED"), 'Form Sa1'!H384, 'Form Sa1'!H112) -> 219298.18 | E19: =IF(OR('General Information'!$C$4="SMELTER", 'General Information'!$C$4="INTEGRATED"), 'Form Sa1'!I384, 'Form Sa1'!I112) -> 0
A20: (iv) | B20: =IF(OR('General Information'!$C$4="SMELTER", 'General Information'!$C$4="INTEGRATED"), 'Form Sa1'!B394, 'Form Sa1'!B116) -> Billets | C20: Tonne | D20: =IF(OR('General Information'!$C$4="SMELTER", 'General Information'!$C$4="INTEGRATED"), 'Form Sa1'!H396, 'Form Sa1'!H118) -> 58980.666 | E20: =IF(OR('General Information'!$C$4="SMELTER", 'General Information'!$C$4="INTEGRATED"), 'Form Sa1'!I396, 'Form Sa1'!I118) -> 0
A21: (v) | B21: =IF(OR('General Information'!$C$4="SMELTER", 'General Information'!$C$4="INTEGRATED"), 'Form Sa1'!B400, 'Form Sa1'!B122) -> Ingot | C21: Tonne | D21: =IF(OR('General Information'!$C$4="SMELTER", 'General Information'!$C$4="INTEGRATED"), 'Form Sa1'!H402, 'Form Sa1'!H124) -> 210775.16 | E21: =IF(OR('General Information'!$C$4="SMELTER", 'General Information'!$C$4="INTEGRATED"), 'Form Sa1'!I402, 'Form Sa1'!I124) -> 0
A22: (vi) | B22: =IF(OR('General Information'!$C$4="SMELTER", 'General Information'!$C$4="INTEGRATED"), 'Form Sa1'!B406, 'Form Sa1'!B128) -> Bars | C22: Tonne | D22: =IF(OR('General Information'!$C$4="SMELTER", 'General Information'!$C$4="INTEGRATED"), 'Form Sa1'!H408, 'Form Sa1'!H130) -> 0 | E22: =IF(OR('General Information'!$C$4="SMELTER", 'General Information'!$C$4="INTEGRATED"), 'Form Sa1'!I408, 'Form Sa1'!I130) -> 0
A23: (vii) | B23: =IF(OR('General Information'!$C$4="SMELTER", 'General Information'!$C$4="INTEGRATED"), 'Form Sa1'!B412, 'Form Sa1'!B134) -> Primary Foundry Alloys | C23: Tonne | D23: =IF(OR('General Information'!$C$4="SMELTER", 'General Information'!$C$4="INTEGRATED"), 'Form Sa1'!H414, 'Form Sa1'!H136) -> 0 | E23: =IF(OR('General Information'!$C$4="SMELTER", 'General Information'!$C$4="INTEGRATED"), 'Form Sa1'!I414, 'Form Sa1'!I136) -> 0
A24: (viii) | B24: =IF(OR('General Information'!$C$4="SMELTER", 'General Information'!$C$4="INTEGRATED"), 'Form Sa1'!B418, 'Form Sa1'!B140) -> Wire Rod | C24: Tonne | D24: =IF(OR('General Information'!$C$4="SMELTER", 'General Information'!$C$4="INTEGRATED"), 'Form Sa1'!H420, 'Form Sa1'!H142) -> 55481.148 | E24: =IF(OR('General Information'!$C$4="SMELTER", 'General Information'!$C$4="INTEGRATED"), 'Form Sa1'!I420, 'Form Sa1'!I142) -> 0
A25: (ix) | B25: =IF(OR('General Information'!$C$4="SMELTER", 'General Information'!$C$4="INTEGRATED"), 'Form Sa1'!B424, 'Form Sa1'!B146) -> Strips | C25: Tonne | D25: =IF(OR('General Information'!$C$4="SMELTER", 'General Information'!$C$4="INTEGRATED"), 'Form Sa1'!H426, 'Form Sa1'!H148) -> 76567.049 | E25: =IF(OR('General Information'!$C$4="SMELTER", 'General Information'!$C$4="INTEGRATED"), 'Form Sa1'!I426, 'Form Sa1'!I148) -> 0
A26: (x) | B26: =IF(OR('General Information'!$C$4="SMELTER", 'General Information'!$C$4="INTEGRATED"), 'Form Sa1'!B430, 'Form Sa1'!B152) -> Others , if Any | C26: Tonne | D26: =IF(OR('General Information'!$C$4="SMELTER", 'General Information'!$C$4="INTEGRATED"), 'Form Sa1'!H433, 'Form Sa1'!H154) -> 42078.393 | E26: =IF(OR('General Information'!$C$4="SMELTER", 'General Information'!$C$4="INTEGRATED"), 'Form Sa1'!I433, 'Form Sa1'!I154) -> 0
A27: (xi) | B27: =IF(OR('General Information'!$C$4="SMELTER", 'General Information'!$C$4="INTEGRATED"), "-",'Form Sa1'!B158) -> - | C27: Tonne | D27: =IF(OR('General Information'!$C$4="SMELTER", 'General Information'!$C$4="INTEGRATED"), "-", 'Form Sa1'!H160) -> - | E27: =IF(OR('General Information'!$C$4="SMELTER", 'General Information'!$C$4="INTEGRATED"), "-", 'Form Sa1'!I160) -> -
A28: (xii) | B28: =IF(OR('General Information'!$C$4="SMELTER", 'General Information'!$C$4="INTEGRATED"), "-", 'Form Sa1'!B164) -> - | C28: Tonne | D28: =IF(OR('General Information'!$C$4="SMELTER", 'General Information'!$C$4="INTEGRATED"), "-", 'Form Sa1'!H167) -> - | E28: =IF(OR('General Information'!$C$4="SMELTER", 'General Information'!$C$4="INTEGRATED"), "-", 'Form Sa1'!I167) -> -
A29: (xiii) | B29: Product (Please add extra rows in case of additional products) | C29: Tonne
A30: (xiv) | B30: =IF(OR('General Information'!$C$4="SMELTER", 'General Information'!$C$4="INTEGRATED"), 'Baseline Parameter'!B73,'Baseline Parameter'!B70) -> Total Equivalent Molten Aluminum Produced | C30: Tonne | D30: =' Summary Sheet'!E102 -> 423703.51 | E30: =' Summary Sheet'!F102 -> 0
A31: B2 | B31: Energy Consumption and GHG Emissions Details
A32: Sr No | B32: Item | C32: Unit | D32: Previous Year | E32: Current Year
C33: (1) | D33: (2) | E33: (3)
A34: (i) | B34: Total Electricity Purchased from Grid/Other Source | C34: Million kwh | D34: =('Form Sa1'!H716/10)+('Form Sa1'!H814/10) -> 118.39134 | E34: =('Form Sa1'!I716/10)+('Form Sa1'!I814/10) -> 0
A35: (ii) | B35: Total Electricity Generated | C35: Million kwh | D35: ='Form Sa1'!H839/10 -> 7087.2925 | E35: ='Form Sa1'!I839/10 -> 0
A36: (iii) | B36: Total Electricity Exported | C36: Million kwh | D36: =('Form Sa1'!H841+'Form Sa1'!H842)/10 -> 178.26538 | E36: =('Form Sa1'!I841+'Form Sa1'!I842)/10 -> 0
A37: (iv) | B37: Total Electrical Energy Consumption | C37: Million kwh | D37: ='Form Sa1'!H845/10 -> 7027.4185 | E37: ='Form Sa1'!I845/10 -> 0
A38: (v) | B38: Total Solid Fuel Consumption | C38: Million kCal | D38: ='Form Sa1'!H1012+'Form Sa1'!H1013+'Form Sa1'!H1014 -> 19863268 | E38: ='Form Sa1'!I1012+'Form Sa1'!I1013+'Form Sa1'!I1014 -> 0
A39: (vi) | B39: Total Liquid Fuel Consumption | C39: Million kCal | D39: ='Form Sa1'!H1171+'Form Sa1'!H1172+'Form Sa1'!H1173+'Form Sa1'!H1174 -> 716331.99 | E39: ='Form Sa1'!I1171+'Form Sa1'!I1172+'Form Sa1'!I1173+'Form Sa1'!I1174 -> 0
A40: (vii) | B40: Total Gaseous Fuel Consumption | C40: Million kCal | D40: ='Form Sa1'!H1217+'Form Sa1'!H1218+'Form Sa1'!H1265 -> 5167.7007 | E40: ='Form Sa1'!I1217+'Form Sa1'!I1218+'Form Sa1'!I1265 -> 0
...

Sheet Form Sa1
A1: FORM-Sa1 (Details of Production and Energy Consumption)
A2: Sector: Aluminium Sector
A3: Name of the Unit | C3: ='General Information'!C3 &" "& 'General Information'!C8 -> HINDALCO INDUSTRIES LIMITED
A4: Sub Sector | C4: ='General Information'!C4 &" "& 'General Information'!C8 -> INTEGRATED
A5: Major Product | C5: ='General Information'!C5:G5 -> MOLTEN ALUMINIUM
A6: Section Links are available here | C6: Production Data | D6: Smelter Process | E6: Boiler Details | F6: Own Generation | G6: Solid Fuel | H6: Gaseous Fuel | I6: Chilled WaterImp/Exp | J6: Energy savings and Investmements
C7: Refinery Process | D7: Anode & Cast House Production | E7: Electricity Consumption | F7: Renewables In-Pant | G7: Liquid Fuel | H7: Steam Imp/Exp | I7: Miscelleneous Data | J7: Process Emissions
A8: S. No | B8: Particulars | C8: Basis/ Calculation | D8: Unit | E8: =IF(K9=1,"Baseline Year","Year 1 (Baseline)") -> Baseline Year | F8: =IF($K$9=1,"Do not Enter any Data","Year 2 (Baseline)") -> Do not Enter any Data | G8: =IF($K$9=3,"Year 3 (Baseline)","Do not Enter any Data") -> Do not Enter any Data | H8: Baseline Year(s) | I8: Current/Assessment /Target Year | J8: Source of Data | K8: Remarks
E9: ='General Information'!C36 -> 2023-24 | F9: =IF('General Information'!C35=1,"",'General Information'!C37) | G9: =IF('General Information'!C35=3,'General Information'!C38," ") | H9: =IF(K9=1,E9,IF(K9=2,E9&" , "&F9,E9&" , "&F9&" , "&G9)) -> 2023-24 | I9: ='General Information'!C33 -> 2025-26 | K9: ='General Information'!C35 -> 1
A10: I | B10: Boundary Coverage for GHG emissions
A11: (a) | B11: Mining & Raw Material Transportation (Quarring, Mining) | C11: Yes/No/Not Applicable
A12: (b) | B12: Fuel and Additives Preparatioin | C12: Yes/No/Not Applicable
A13: (c) | B13: Bauxite/Limestone Crusher and raw material preparation | C13: Yes/No/Not Applicable
A14: (d) | B14: Caustic Soda Production | C14: Yes/No/Not Applicable | H14: Yes
A15: (e) | B15: Clacined Lime Production | C15: Yes/No/Not Applicable
A16: (f) | B16: Red Mud Handling System | C16: Yes/No/Not Applicable
A17: (g) | B17: Rotary Kiln or Fluidized Bed Calciner | C17: Yes/No/Not Applicable
A18: (h) | B18: Aluminium Floride Production | C18: Yes/No/Not Applicable
A19: (i) | B19: Soda Ash Production | C19: Yes/No/Not Applicable
A20: (j) | B20: Anode/Cathode Production | C20: Yes/No/Not Applicable
A21: (k) | B21: Petroleum Coke Production | C21: Yes/No/Not Applicable
A22: (l) | B22: Molten Aluminium Handling and Ingot casting | C22: Yes/No/Not Applicable
A23: (m) | B23: Scrap Recycling | C23: Yes/No/Not Applicable
A24: (n) | B24: Internal Transportation (Process and Material) | C24: Yes/No/Not Applicable
A25: (o) | B25: On Site Power generation | C25: Yes/No/Not Applicable
A26: (p) | B26: Admin Buildings | C26: Yes/No/Not Applicable
A27: II | B27: Emissions Source Coverage
A28: (a) | B28: Solid Fuel Combustion in CPP/CHP | C28: Yes/No/Not Applicable
A29: (b) | B29: Liquid Fuel Combustion in CPP/CHP | C29: Yes/No/Not Applicable
A30: (c) | B30: Gaseous Fuel Combustion in CPP/CHP | C30: Yes/No/Not Applicable
A31: (d) | B31: Solid Fuel Combustion in Process (Refinery/Smelting) | C31: Yes/No/Not Applicable
A32: (e) | B32: Liquid Fuel Combustion in Process (Refinery/Smelting) | C32: Yes/No/Not Applicable
A33: (f) | B33: Gaseous Fuel Combustion in Process (Refinery/Smelting) | C33: Yes/No/Not Applicable
A34: (g) | B34: Aluminium Smelting Process CO2 emissions | C34: Yes/No/Not Applicable
A35: (h) | B35: PFC Emissions from Smelting | C35: Yes/No/Not Applicable
A36: (i) | B36: Emissions from Coke Production | C36: Yes/No/Not Applicable
A37: (j) | B37: Emission from melting and holding | C37: Yes/No/Not Applicable
A38: (k) | B38: Emissions resulting from Soda Ash Use | C38: Yes/No/Not Applicable
A39: (l) | B39: Emissions from Lime Production | C39: Yes/No/Not Applicable
A40: (m) | B40: Emission from Purchased Electricity | C40: Yes/No/Not Applicable
...

Sheet Annex CPP
A1: Form- Sa1 Captive Power Plant Details
A2: Name of the Unit | C2: ='Form Sa1'!C3:K3 -> HINDALCO INDUSTRIES LIMITED
A3: 1 | B3: OEM Curve / HBD data
A4: 1.a | B4: Units | C4: Design Capacity | D4: As Provided by Original Equipment Manaufacturer (OEM) | G4: Curve Equation/ (R2) | L4: Load Vs Heat Rate or HBD Curve (at 100% Load) | N4: Source of Data | Q4: Remarks
D5: Boiler Efficiency | E5: Turbine Heat Rate | F5: Unit Heat Rate * | G5: OEM Curve OR HBD data curve | I5: Constant 1 | J5: Constant 2 | K5: Constant 3 | L5: Turbine Heat Rate
C6: MW | D6: % | E6: kcal/kwh | F6: kcal/kwh | G6: y=ax2-bx+c | H6: R2 | I6: a | J6: b | K6: c | L6: kcal/kwh
A7: i | B7: Unit-1 | F7: =IFERROR(E7*100/D7,0) -> 2679.5181
A8: ii | B8: Unit-2 | F8: =IFERROR(E8*100/D8,0) -> 2679.5181
A9: iii. | B9: Unit-3 | F9: =IFERROR(E9*100/D9,0) -> 2544.5783
A10: iv. | B10: Unit-4 | F10: =IFERROR(E10*100/D10,0) -> 2544.5783
A11: v | B11: Unit-5 | F11: =IFERROR(E11*100/D11,0) -> 2547.3054
A12: vi | B12: Unit-6 | F12: =IFERROR(E12*100/D12,0) -> 2606.6066
A13: vii | B13: Unit-7 | F13: =IFERROR(E13*100/D13,0) -> 2606.6066
A14: viii | B14: Unit-8 | F14: =IFERROR(E14*100/D14,0) -> 2661.8619
A15: ix | B15: Unit-9 | F15: =IFERROR(E15*100/D15,0) -> 2572.5845
A16: x | B16: Unit-10 | F16: =IFERROR(E16*100/D16,0) -> 2572.5845
A17: 1.b | B17: Station Design Data Details *** | C17: =SUM(C7:C16) -> 829.58 | D17: =IF(SUM(C7:C16)=0,0,(D7*C7+D8*C8+D9*C9+D10*C10+D11*C11+D12*C12+D13*C13+D14*C14+D15*C15+D16*C16)/SUM(C7:C16)) -> 83.338702 | E17: =(E7*C7+E8*C8+E9*C9+E10*C10+E11*C11+E12*C12+E13*C13+E14*C14+E15*C15+E16*C16)/SUM(C7:C16) -> 2167.7201 | F17: =IFERROR((F7*C7+F8*C8+F9*C9+F10*C10+F11*C11+F12*C12+F13*C13+F14*C14+F15*C15+F16*C16)/SUM(C7:C16),0) -> 2601.1802
B18: *** Station Design Heat Rate = [(DGHR 1 x Capacity 1 + DGHR 2 x Capacity2 + -----------) / (Total Capacity of Station)]
B19: ** To be indicated only if OEM certified design or PG Test report is available and the same can be produced as documentry proof, whenever required. If gas/liquid fuel is used, the Design/PG value for gas/liquied fuel may be given separately.
B20: * Unit Heat Rate (kcal/kWh) = [ Turbine Heat Rate (kcal/kWh) / Boiler Efficiency (%) ]
A21: 2 | B21: Unit wise Operating Data Details
A22: 2.a | B22: Units | C22: ='NF - 5 Power Mix'!E4 -> Baseline/Previous Year 2023-24 | K22: ='NF - 5 Power Mix'!F4 -> Assesment year/ Current Year FY 2025-26 | S22: Source of Data
C23: Operating Load | E23: ULF | G23: Gross Generation | I23: Unit Gross Heat Rate # | K23: Operating Load | M23: ULF | O23: Gross Generation | Q23: Unit Gross Heat Rate #
C24: MW | E24: % | G24: Lakh Units | I24: kcal/kwh | K24: MW | M24: % | O24: Lakh Units | Q24: kcal/kwh
A25: i | B25: Unit-1
A26: ii | B26: Unit-2
A27: iii. | B27: Unit-3
A28: iv. | B28: Unit-4
A29: v | B29: Unit-5
A30: vi | B30: Unit-6
A31: vii | B31: Unit-7
A32: viii | B32: Unit-8
A33: ix | B33: Unit-9
A34: x | B34: Unit-10
A35: 2.b | B35: Station Operating Data Details ## | C35: =SUM(C25:D34) -> 755.397 | E35: =IFERROR((E25*G25+E26*G26+E27*G27+E28*G28+E29*G29+E30*G30+E31*G31+E32*G32+E33*G33+E34*G34)/G35,0) -> 0.91627028 | G35: =SUM(G25:H34) -> 66354.072 | I35: =IFERROR(((G25*I25+G26*I26+G27*I27+G28*I28+G29*I29+G30*I30+G31*I31+G32*I32+G33*I33+G34*I34)/G35),0) -> 2584 | K35: =SUM(K25:L34) -> 0 | M35: =IFERROR((M25*O25+M26*O26+M27*O27+M28*O28+M29*O29+M30*O30+M31*O31+M32*O32+M33*O33+M34*O34)/O35,0) -> 0 | O35: =SUM(O25:P34) -> 0 | Q35: =IFERROR((O25*Q25+O26*Q26+O27*Q27+O28*Q28+O29*Q29+O30*Q30+O31*Q31+O32*Q32+O33*Q33+O34*Q34)/O35,0) -> 0
A37: 2.c | B37: Station Auxillary Power Consumption
B38: # Unit Heat Rate (kcal/kWh) = [ Turbine Heat Rate (kcal/kWh) / Boiler Efficiency (%) ]
B39: ## Station Operating Gross Heat Rate = [(OGHR 1 x Generation 1 + OGHR 2 x Generation 2 + -----------) / (Total Generation of Station)]
A40: 3 | B40: Plant Load Factor Details
A41: 3.a | B41: Loss of PLF due to non-availability of fuel/schedule/backing down/any external factor/Unforeseen factors
...

Sheet  Summary Sheet
A1: Form-Sa1 (Summary Sheet )
A2: Sector: Aluminum Sector
B3: Sub-Sector | C3: ='General Information'!G4 -> INTEGRATED
A4: S. No | B4: Particulars | C4: Basis/Formula | D4: Unit | E4: ='Form Sa1'!H8 -> Baseline Year(s) | F4: Current/Target Year
E5: ='Form Sa1'!H9 -> 2023-24 | F5: ='Form Sa1'!I9 -> 2025-26
B6: Details of Production
A7: A1 | B7: Refinery
A8: A1.1 | B8: Production and Capacity Utilization
A9: i | B9: Total Hydrate Aluminia Production | C9: Baseline Parameter'! (A1 (i) ) | D9: Tonne | E9: ='Baseline Parameter'!E8 -> 565600 | F9: ='Baseline Parameter'!F8 -> 0
A10: ii | B10: Total Calcined Alumina Production | C10: Baseline Parameter'! (A1 (ii) ) | D10: Tonne | E10: ='Baseline Parameter'!E9 -> 561459 | F10: ='Baseline Parameter'!F9 -> 0
A11: iii | B11: Capacity Utilization (Hydrate Alumina) | C11: Form Sa1'! {A1(v)} | D11: % | E11: ='Form Sa1'!H48 -> 80.8 | F11: ='Form Sa1'!I48 -> 0
A12: iv | B12: Capacity Utilization (Calcined Alumina) | C12: Form Sa1'! {A1(vi)} | D12: % | E12: ='Form Sa1'!H49 -> 81.946873 | F12: ='Form Sa1'!I49 -> 0
A13: A1.2 | B13: Hydrate Alumina (Intermediary product for Reinery)
A14: i | B14: Hydrate Alumina Opening Stock | C14: Form Sa1'! {A3.1.a.(iii)} | D14: Tonne | E14: ='Form Sa1'!H66 -> 30580.066 | F14: ='Form Sa1'!I66 -> 0
A15: ii | B15: Hydrate Alumina Closing stock | C15: Form Sa1'! {A3.1.a.(iv)} | D15: Tonne | E15: ='Form Sa1'!H67 -> 34626.579 | F15: ='Form Sa1'!I67 -> 0
A16: iii | B16: Hydrate Alumina Stock | C16: A1.2 (ii)-A1.2(i) | D16: Tonne | E16: =E15-E14 -> 4046.513 | F16: =F15-F14 -> 0
A17: iv | B17: Hydrate Alumina Exported | C17: Baseline Parameter'!{A1.1.(xii)} | D17: Tonne | E17: ='Baseline Parameter'!E25 -> 0 | F17: ='Baseline Parameter'!F25 -> 0
A18: v | B18: Hydrate Alumina Imported | C18: Baseline Parameter'!{A1.1.(xiii)} | D18: Tonne | E18: ='Baseline Parameter'!E26 -> 0 | F18: ='Baseline Parameter'!F26 -> 0
A19: vi | B19: Total Hydrate Aluminia Export | C19: A1.2(iv)+A1.2(iii) | D19: Tonne | E19: =IF(E16>0, (E17+E16), (E17)) -> 4046.513 | F19: =IF(F16>0, (F17+F16), (F17)) -> 0
A20: vii | B20: Total Hydrate Aluminia Import | C20: A1.2(v)-A1.2(iii) | D20: Tonne | E20: =IF(E16<0,E18-E16, (E18)) -> 0 | F20: =IF(F16<0,F18-F16, (F18)) -> 0 | G20: =IF(G16<0,G18-G16, (G18)) -> 0 | H20: =IF(H16<0,H18-H16, (H18)) -> 0 | I20: =IF(I16<0,I18-I16, (I18)) -> 0 | J20: =IF(J16<0,J18-J16, (J18)) -> 0 | K20: =IF(K16<0,K18-K16, (K18)) -> 0 | L20: =IF(L16<0,L18-L16, (L18)) -> 0 | ... IU20: =IF(IU16<0,IU18-IU16, (IU18)) -> 0
A21: A1.3 | B21: Calicined Alumina (Intermediary Product for Integrated Process)
A22: i | B22: Calcined Alumina opening stock (Integrated Process) | C22: Form Sa1'! {c(i)} | D22: Tonne | E22: ='Form Sa1'!H98 -> 44543.327 | F22: ='Form Sa1'!I98 -> 0
A23: ii | B23: Calcined Alumina Closing stock (Integrated Process) | C23: Form Sa1'! {c(ii)} | D23: Tonne | E23: ='Form Sa1'!H99 -> 49464.495 | F23: ='Form Sa1'!I99 -> 0
A24: iii | B24: Calcined Alumina Stock (Integrated Process) | C24: A1.3 (ii)-A1.3(i) | D24: Tonne | E24: =E23-E22 -> 4921.168 | F24: =F23-F22 -> 0
A25: iv | B25: Calcined Alumina Exported (Integrated Process) | C25: Baseline Parameter'! {A1.1.(xiv)} | D25: Tonne | E25: ='Baseline Parameter'!E27 -> 0 | F25: ='Baseline Parameter'!F27 -> 0
A26: v | B26: Calcined Alumina Imported (Intergated Process) | C26: Baseline Parameter'! {A1.1.(xv)} | D26: Tonne | E26: ='Baseline Parameter'!E28 -> 244856.09 | F26: ='Baseline Parameter'!F28 -> 0
A27: vi | B27: Total Calcined Alumina Export (Integrated Process) | C27: A1.3(iv)+A1.3(iii) | D27: Tonne | E27: =IF(E24>0, (E25+E24), (E25)) -> 4921.168 | F27: =IF(F24>0, (F25+F24), (F25)) -> 0
A28: vii | B28: Total Calcined Alumina Import (Intergated Process) | C28: A1.3(v)-A1.3(iii) | D28: Tonne | E28: =IF(E24<0, E26-E24, (E26)) -> 244856.09 | F28: =IF(F24<0, F26-F24, (F26)) -> 0
A30: A2 | B30: Smelter Process
A31: A2.1 | B31: Production and Capacity Utilization
A32: i | B32: Total Molten Aluminium Production | C32: Baseline Parameter'! {A2(i)} | D32: Tonne | E32: ='Baseline Parameter'!E31 -> 410661.74 | F32: ='Baseline Parameter'!F31 -> 0
A33: ii | B33: Total Cast House Production | C33: Baseline Parameter'! {A2(ii)} | D33: Tonne | E33: ='Baseline Parameter'!E32 -> 381860.33 | F33: ='Baseline Parameter'!F32 -> 0
A34: iii | B34: Capacity Utilization (Molten Aluminum) | C34: Form Sa1'! {A2 (v)} | D34: % | E34: ='Form Sa1'!H58 -> 119.03239 | F34: ='Form Sa1'!I58 -> 0
A35: iv | B35: Capacity Utilization (Cast House) | C35: Form Sa1'! {A2 (vi)} | D35: % | E35: ='Form Sa1'!H59 -> 137.21176 | F35: ='Form Sa1'!I59 -> 0
B37: Details of Energy Consumption
A38: B | B38: Total Thermal Energy Consumption | C38: [Fuel Consumed (Lakh Tonnene) X GCV of Fuel (Kcal/Kg)] X 100 - 'Baseline Parameter'! (H) | D38: Million kcal | E38: ='Baseline Parameter'!E124 -> 20584768 | F38: ='Baseline Parameter'!F124 -> 0
A39: C | B39: Total Electricity consumed within the plant | C39: {(Electricity Generated through CPP+Electricity generation through DG Set + Electricity generation through WHR+ Electricity Purchased from Grid) - Electricity exported to Grid} -'Baseline Parameter'!(F4) | D39: Lakh kWh | E39: ='NF - 5 Power Mix'!E24 -> 70274.185 | F39: ='NF - 5 Power Mix'!F24 -> 0
A40: D | B40: Electricity Purchased from Grid | C40: Average of year 2007-08, 2008-09 and 2009-10 -'Baseline Parameter'!(D 1 (i)) | D40: Lakh kWh | E40: ='NF - 5 Power Mix'!E6 -> 1144.79 | F40: ='NF - 5 Power Mix'!F6 -> 0
A41: E | B41: Electricity Exported to Grid/Colony/Others from CPP | C41: Average of year 2007-08, 2008-09 and 2009-10 -'Baseline Parameter'! (F2) | D41: Lakh kWh | E41: ='Form Sa1'!H841+'Form Sa1'!H842 -> 1782.6538 | F41: ='Form Sa1'!I841+'Form Sa1'!I842 -> 0
A42: F | B42: Total Energy Consumed (Thermal+Electrical) | C42: [Total Thermal Energy (Million kcal)+{(Total Electricity purchased from grid (Lakh kWh) X 860)-Electricity exported (Lakh kWh) X weighted generation net heat reate- 'NF-5 Power mix'!E33 kcal/kWh}/10] ----[(B)+{(D)*860/10}-{(E)*2717/10}] | D42: Million kcal | E42: =E38+((E40+'NF - 5 Power Mix'!E14+'NF - 5 Power Mix'!E15)*860/10)+((('Form Sa1'!H835)*860)/10)+('Form Sa1'!H814*'Form Sa1'!H816/10)-'NF - 5 Power Mix'!E21-'NF - 5 Power Mix'!E22 -> 20189374 | F42: =F38+((F40+'NF - 5 Power Mix'!F14+'NF - 5 Power Mix'!F15)*860/10)+((('Form Sa1'!I835)*860)/10)+('Form Sa1'!I814*'Form Sa1'!I816/10)-'NF - 5 Power Mix'!F21-'NF - 5 Power Mix'!F22 -> #DIV/0! | G42: =G38+((G40+'NF - 5 Power Mix'!G14+'NF - 5 Power Mix'!G15)*860/10)+((('Form Sa1'!J835)*860)/10)+('Form Sa1'!J814*'Form Sa1'!J816/10)-'NF - 5 Power Mix'!G21-'NF - 5 Power Mix'!G22 -> 0 | H42: =H38+((H40+'NF - 5 Power Mix'!H14+'NF - 5 Power Mix'!H15)*860/10)+((('Form Sa1'!K835)*860)/10)+('Form Sa1'!K814*'Form Sa1'!K816/10)-'NF - 5 Power Mix'!H21-'NF - 5 Power Mix'!H22 -> 0 | I42: =I38+((I40+'NF - 5 Power Mix'!I14+'NF - 5 Power Mix'!I15)*860/10)+((('Form Sa1'!L835)*860)/10)+('Form Sa1'!L814*'Form Sa1'!L816/10)-'NF - 5 Power Mix'!I21-'NF - 5 Power Mix'!I22 -> 0 | J42: =J38+((J40+'NF - 5 Power Mix'!J14+'NF - 5 Power Mix'!J15)*860/10)+((('Form Sa1'!M835)*860)/10)+('Form Sa1'!M814*'Form Sa1'!M816/10)-'NF - 5 Power Mix'!J21-'NF - 5 Power Mix'!J22 -> 0 | K42: =K38+((K40+'NF - 5 Power Mix'!K14+'NF - 5 Power Mix'!K15)*860/10)+((('Form Sa1'!N835)*860)/10)+('Form Sa1'!N814*'Form Sa1'!N816/10)-'NF - 5 Power Mix'!K21-'NF - 5 Power Mix'!K22 -> 0 | L42: =L38+((L40+'NF - 5 Power Mix'!L14+'NF - 5 Power Mix'!L15)*860/10)+((('Form Sa1'!O835)*860)/10)+('Form Sa1'!O814*'Form Sa1'!O816/10)-'NF - 5 Power Mix'!L21-'NF - 5 Power Mix'!L22 -> 0 | ... XFA42: =XFA38+((XFA40+'NF - 5 Power Mix'!XFA14+'NF - 5 Power Mix'!XFA15)*860/10)+((('Form Sa1'!XFD835)*860)/10)+('Form Sa1'!XFD814*'Form Sa1'!XFD816/10)-'NF - 5 Power Mix'!XFA21-'NF - 5 Power Mix'!XFA22 -> 0 | XFB42: =XFB38+((XFB40+'NF - 5 Power Mix'!XFB14+'NF - 5 Power Mix'!XFB15)*860/10)+((('Form Sa1'!#REF!)*860)/10)+('Form Sa1'!#REF!*'Form Sa1'!#REF!/10)-'NF - 5 Power Mix'!XFB21-'NF - 5 Power Mix'!XFB22 -> #REF! | XFC42: =XFC38+((XFC40+'NF - 5 Power Mix'!XFC14+'NF - 5 Power Mix'!XFC15)*860/10)+((('Form Sa1'!#REF!)*860)/10)+('Form Sa1'!#REF!*'Form Sa1'!#REF!/10)-'NF - 5 Power Mix'!XFC21-'NF - 5 Power Mix'!XFC22 -> #REF!
...

